<?xml version="1.0" ?>
<!-- =================================================================================== -->
<!-- |    This document was autogenerated by xacro from franka_description/robots/panda.urdf.xacro | -->
<!-- |    EDITING THIS FILE BY HAND IS NOT RECOMMENDED                                 | -->
<!-- =================================================================================== -->
<robot name="panda">
  <!--: Minimum safety distance [m] by which the collision volumes are expanded and which is enforced during robot motions -->
  <!-- arm_id: Namespace of the panda arm. Serves to differentiate between arms in case of multiple instances. -->
  <!-- <xacro:include filename="$(find franka_description)/robots/hand.xacro" /> -->
  <!-- fix the robot to the Gazebo world coordinate system  -->
  <link name="world"/>
  <joint name="robot_to_world" type="fixed">
    <parent link="world"/>
    <child link="panda_link0"/>
    <origin rpy="0.0 0.0 0.0" xyz="0.0 0.0 0.0"/>
    <dynamics damping="1.0"/>
  </joint>
  <!-- link/joint 0 -->
  <link name="panda_link0">
    <inertial>
      <mass value="1.937868"/>
      <origin rpy="0 0 0" xyz="-0.025566 -2.88e-05 0.057332"/>
      <inertia ixx="1" ixy="0" ixz="0" iyy="1" iyz="0" izz="1"/>
    </inertial>
    <visual>
      <origin rpy="0 0 0" xyz="0 0 0"/>
      <geometry>
        <mesh filename="package://franka_description/meshes/visual/link0.dae"/>
      </geometry>
      <material name="">
        <color rgba="1 1 1 1"/>
      </material>
    </visual>
    <collision>
      <origin rpy="0 0 0" xyz="0 0 0"/>
      <geometry>
        <mesh filename="package://franka_description/meshes/collision/link0.stl"/>
      </geometry>
    </collision>
  </link>
  <!-- link/joint 1 -->
  <link name="panda_link1">
    <inertial>
      <origin rpy="0 0 0" xyz="3.875e-03 2.081e-03 -0.1750"/>
      <mass value="4.970684"/>
      <inertia ixx="0.551121276649726" ixy="-9.891702555950000e-05" ixz="0.003401254912500" iyy="0.554308164573063" iyz="0.017358801154300" izz="0.009020836222789"/>
    </inertial>
    <visual>
      <origin rpy="0 0 0" xyz="0 0 0"/>
      <geometry>
        <mesh filename="package://franka_description/meshes/visual/link1.dae"/>
      </geometry>
      <material name="">
        <color rgba="1 1 1 1"/>
      </material>
    </visual>
    <collision>
      <origin rpy="0 0 0" xyz="0 0 0"/>
      <geometry>
        <mesh filename="package://franka_description/meshes/collision/link1.stl"/>
      </geometry>
    </collision>
  </link>
  <joint name="panda_joint1" type="revolute">
    <safety_controller k_position="100.0" k_velocity="40.0" soft_lower_limit="-2.8973" soft_upper_limit="2.8973"/>
    <origin rpy="0 0 0" xyz="0 0 0.333"/>
    <parent link="panda_link0"/>
    <child link="panda_link1"/>
    <axis xyz="0 0 1"/>
    <limit effort="87" lower="-2.8973" upper="2.8973" velocity="2.1750"/>
    <dynamics damping="1.0"/>
  </joint>
  <!-- link/joint 2 -->
  <link name="panda_link2">
    <inertial>
      <origin rpy="0 0 0" xyz="-3.141e-03 -2.872e-02 3.495e-03"/>
      <mass value="0.646926"/>
      <inertia ixx="0.007420488375978" ixy="-0.003866641116064" ixz="0.010246898178992" iyy="0.028095715287805" iyz="6.390638970536000e-04" izz="0.025455008098310"/>
    </inertial>
    <visual>
      <origin rpy="0 0 0" xyz="0 0 0"/>
      <geometry>
        <mesh filename="package://franka_description/meshes/visual/link2.dae"/>
      </geometry>
      <material name="">
        <color rgba="1 1 1 1"/>
      </material>
    </visual>
    <collision>
      <origin rpy="0 0 0" xyz="0 0 0"/>
      <geometry>
        <mesh filename="package://franka_description/meshes/collision/link2.stl"/>
      </geometry>
    </collision>
  </link>
  <joint name="panda_joint2" type="revolute">
    <safety_controller k_position="100.0" k_velocity="40.0" soft_lower_limit="-1.7628" soft_upper_limit="1.7628"/>
    <origin rpy="-1.5707963267948966 0 0" xyz="0 0 0"/>
    <parent link="panda_link1"/>
    <child link="panda_link2"/>
    <axis xyz="0 0 1"/>
    <limit effort="1000000000000" lower="-1.7628" upper="1.7628" velocity="1000000000000"/>
    <limit effort="87" lower="-1.7628" upper="1.7628" velocity="2.1750"/>
    <dynamics damping="1.0"/>
  </joint>
  <!-- link/joint 3 -->
  <link name="panda_link3">
    <inertial>
      <origin rpy="0 0 0" xyz="2.7518e-02 3.9252e-02 -6.6502e-02"/>
      <mass value="3.228604"/>
      <inertia ixx="0.017989073985929" ixy="-0.001273666859324" ixz="-0.017304351893438" iyy="0.019431618000394" iyz="-0.021232742878160" izz="0.003410797707480"/>
    </inertial>
    <visual>
      <origin rpy="0 0 0" xyz="0 0 0"/>
      <geometry>
        <mesh filename="package://franka_description/meshes/visual/link3.dae"/>
      </geometry>
      <material name="">
        <color rgba="1 1 1 1"/>
      </material>
    </visual>
    <collision>
      <origin rpy="0 0 0" xyz="0 0 0"/>
      <geometry>
        <mesh filename="package://franka_description/meshes/collision/link3.stl"/>
      </geometry>
    </collision>
  </link>
  <joint name="panda_joint3" type="revolute">
    <safety_controller k_position="100.0" k_velocity="40.0" soft_lower_limit="-2.8973" soft_upper_limit="2.8973"/>
    <origin rpy="1.5707963267948966 0 0" xyz="0 -0.316 0"/>
    <parent link="panda_link2"/>
    <child link="panda_link3"/>
    <axis xyz="0 0 1"/>
    <limit effort="87" lower="-2.8973" upper="2.8973" velocity="2.1750"/>
    <dynamics damping="1.0"/>
  </joint>
  <!-- link/joint 4 -->
  <link name="panda_link4">
    <inertial>
      <origin rpy="0 0 0" xyz="-5.317e-02 1.04419e-01 2.7454e-02"/>
      <mass value="3.587895"/>
      <inertia ixx="-0.015971270250860" ixy="-0.012123843173626" ixz="-0.006569355026276" iyy="0.006704569575549" iyz="0.018926487577369" izz="-0.020940149052540"/>
    </inertial>
    <visual>
      <origin rpy="0 0 0" xyz="0 0 0"/>
      <geometry>
        <mesh filename="package://franka_description/meshes/visual/link4.dae"/>
      </geometry>
      <material name="">
        <color rgba="1 1 1 1"/>
      </material>
    </visual>
    <collision>
      <origin rpy="0 0 0" xyz="0 0 0"/>
      <geometry>
        <mesh filename="package://franka_description/meshes/collision/link4.stl"/>
      </geometry>
    </collision>
  </link>
  <joint name="panda_joint4" type="revolute">
    <!--<safety_controller k_position="100.0" k_velocity="40.0" soft_lower_limit="-3.0718" soft_upper_limit="-0.0698"/>-->
    <origin rpy="1.5707963267948966 0 0" xyz="0.0825 0 0"/>
    <parent link="panda_link3"/>
    <child link="panda_link4"/>
    <axis xyz="0 0 1"/>
    <!--<limit effort="87" lower="${-3.0718+pi/2}" upper="${-0.0698+pi/2}" velocity="2.1750"/>-->
    <limit effort="87" lower="-3.0718" upper="-0.0698" velocity="2.1750"/>
    <dynamics damping="1.0"/>
  </joint>
  <!-- link/joint 5 -->
  <link name="panda_link5">
    <inertial>
      <origin rpy="0 0 0" xyz="-1.1953e-02 4.1065e-02 -3.8437e-02"/>
      <mass value="1.225946"/>
      <inertia ixx="0.031670429041964" ixy="-0.002718755526673" ixz="-0.003473754482437" iyy="0.027487627674740" iyz="-0.001706052052098" izz="0.006384489237171"/>
    </inertial>
    <visual>
      <origin rpy="0 0 0" xyz="0 0 0"/>
      <geometry>
        <mesh filename="package://franka_description/meshes/visual/link5.dae"/>
      </geometry>
      <material name="">
        <color rgba="1 1 1 1"/>
      </material>
    </visual>
    <collision>
      <origin rpy="0 0 0" xyz="0 0 0"/>
      <geometry>
        <mesh filename="package://franka_description/meshes/collision/link5.stl"/>
      </geometry>
    </collision>
  </link>
  <joint name="panda_joint5" type="revolute">
    <safety_controller k_position="100.0" k_velocity="40.0" soft_lower_limit="-2.8973" soft_upper_limit="2.8973"/>
    <origin rpy="-1.5707963267948966 0 0" xyz="-0.0825 0.384 0"/>
    <parent link="panda_link4"/>
    <child link="panda_link5"/>
    <axis xyz="0 0 1"/>
    <limit effort="12" lower="-2.8973" upper="2.8973" velocity="2.6100"/>
    <dynamics damping="1.0"/>
  </joint>
  <!-- link/joint 6 -->
  <link name="panda_link6">
    <inertial>
      <origin rpy="0 0 0" xyz="6.0149e-02 -1.4117e-02 -1.0517e-02"/>
      <mass value="1.666555"/>
      <inertia ixx="0.001447539641829" ixy="-0.001306110902883" ixz="-0.002212241082781" iyy="-0.001859766133107" iyz="5.884309026853950e-04" izz="-9.285602302389487e-04"/>
    </inertial>
    <visual>
      <origin rpy="0 0 0" xyz="0 0 0"/>
      <geometry>
        <mesh filename="package://franka_description/meshes/visual/link6.dae"/>
      </geometry>
      <material name="">
        <color rgba="1 1 1 1"/>
      </material>
    </visual>
    <collision>
      <origin rpy="0 0 0" xyz="0 0 0"/>
      <geometry>
        <mesh filename="package://franka_description/meshes/collision/link6.stl"/>
      </geometry>
    </collision>
  </link>
  <joint name="panda_joint6" type="revolute">
    <!--<safety_controller k_position="100.0" k_velocity="40.0" soft_lower_limit="-0.0175" soft_upper_limit="3.7525"/>-->
    <origin rpy="1.5707963267948966 0 0" xyz="0 0 0"/>
    <parent link="panda_link5"/>
    <child link="panda_link6"/>
    <axis xyz="0 0 1"/>
    <!--<limit effort="12" lower="${-0.0175-pi/2}" upper="${3.7525-pi/2}" velocity="2.6100"/>-->
    <limit effort="12" lower="-0.0175" upper="3.7525" velocity="2.6100"/>
    <dynamics damping="1.0"/>
  </joint>
  <!-- link/joint 7 -->
  <link name="panda_link7">
    <inertial>
      <origin rpy="0 0 0" xyz="1.0517e-02 -4.252e-03 6.1597e-02"/>
      <mass value="7.35522e-01"/>
      <inertia ixx="0.009711991609050" ixy="-4.608912816842480e-04" ixz="-7.195173382162220e-04" iyy="0.007154935387572" iyz="-9.336408935917680e-04" izz="0.004720348032639"/>
    </inertial>
    <visual>
      <origin rpy="0 0 0" xyz="0 0 0"/>
      <geometry>
        <mesh filename="package://franka_description/meshes/visual/link7.dae"/>
      </geometry>
    </visual>
    <collision>
      <origin rpy="0 0 0" xyz="0 0 0"/>
      <geometry>
        <mesh filename="package://franka_description/meshes/collision/link7.stl"/>
      </geometry>
    </collision>
  </link>
  <joint name="panda_joint7" type="revolute">
    <safety_controller k_position="100.0" k_velocity="40.0" soft_lower_limit="-2.8973" soft_upper_limit="2.8973"/>
    <origin rpy="1.5707963267948966 0 0" xyz="0.088 0 0"/>
    <parent link="panda_link6"/>
    <child link="panda_link7"/>
    <axis xyz="0 0 1"/>
    <limit effort="12" lower="-2.8973" upper="2.8973" velocity="2.6100"/>
    <dynamics damping="1.0"/>
  </joint>
  <link name="panda_link8">
    <inertial>
      <origin rpy="0 0 0" xyz="0 0 0.025"/>
      <mass value="0.1"/>
      <inertia ixx="3.64583e-03" ixy="0.0" ixz="0.0" iyy="3.64583e-03" iyz="0.0" izz="3.125e-03"/>
    </inertial>
    <visual>
      <geometry>
        <cylinder length="0.05" radius="0.025"/>
      </geometry>
      <origin rpy="0 0 0" xyz="0 0 0.025"/>
    </visual>
    <collision>
      <geometry>
        <cylinder length="0.05" radius="0.025"/>
      </geometry>
      <origin rpy="0 0 0" xyz="0 0 0.025"/>
    </collision>
  </link>
  <joint name="panda_joint8" type="fixed">
    <origin rpy="0 0 0" xyz="0 0 0.107"/>
    <parent link="panda_link7"/>
    <child link="panda_link8"/>
    <axis xyz="0 0 0"/>
  </joint>
  <link name="panda_link9">
    <inertial>
      <origin rpy="0 0 0" xyz="0 0 0"/>
      <mass value="0.1"/>
      <inertia ixx="0.000025" ixy="0.0" ixz="0.0" iyy="0.000025" iyz="0.0" izz="0.000025"/>
    </inertial>
    <visual>
      <geometry>
        <sphere radius="0.025"/>
      </geometry>
      <origin rpy="0 0 0" xyz="0 0 0"/>
    </visual>
    <collision>
      <geometry>
        <sphere radius="0.025"/>
      </geometry>
      <origin rpy="0 0 0" xyz="0 0 0"/>
    </collision>
  </link>
  <joint name="panda_joint9" type="fixed">
    <origin rpy="0 0 0" xyz="0 0 0.05"/>
    <parent link="panda_link8"/>
    <child link="panda_link9"/>
    <axis xyz="0 0 0"/>
  </joint>
  <!-- ball joint -->
  <link name="arm_to_ball">
    <inertial>
      <mass value="0.1"/>
      <inertia ixx="5.8083e-4" ixy="0" ixz="0" iyy="3.0833e-5" iyz="0" izz="5.9083e-4"/>
    </inertial>
  </link>
  <joint name="panda_joint_ball_x" type="revolute">
    <origin rpy="0 0 0" xyz="0 0 0"/>
    <parent link="panda_link9"/>
    <child link="arm_to_ball"/>
    <axis xyz="1 0 0"/>
    <limit effort="12" lower="-31.41592653589793" upper="31.41592653589793" velocity="2.6100"/>
    <dynamics damping="1"/>
  </joint>
  <link name="ball">
    <inertial>
      <mass value="0.1"/>
      <inertia ixx="5.8083e-4" ixy="0" ixz="0" iyy="3.0833e-5" iyz="0" izz="5.9083e-4"/>
    </inertial>
  </link>
  <joint name="panda_joint_ball_y" type="revolute">
    <origin rpy="0 0 0" xyz="0 0 0"/>
    <parent link="arm_to_ball"/>
    <child link="ball"/>
    <axis xyz="0 1 0"/>
    <limit effort="12" lower="-31.41592653589793" upper="31.41592653589793" velocity="2.6100"/>
    <dynamics damping="1"/>
  </joint>
  <link name="panda_link10">
    <inertial>
      <origin rpy="0 0 0" xyz="0 0 0.0125"/>
      <mass value="0.1"/>
      <inertia ixx="3.64583e-03" ixy="0.0" ixz="0.0" iyy="3.64583e-03" iyz="0.0" izz="3.125e-03"/>
    </inertial>
    <visual>
      <geometry>
        <cylinder length="0.025" radius="0.01"/>
      </geometry>
      <origin rpy="0 0 0" xyz="0 0 0.0125"/>
    </visual>
    <collision>
      <geometry>
        <cylinder length="0.025" radius="0.01"/>
      </geometry>
      <origin rpy="0 0 0" xyz="0 0 0.0125"/>
    </collision>
  </link>
  <joint name="panda_joint_ball_z" type="continuous">
    <origin rpy="0 0 3.141592" xyz="0 0 0.025"/>
    <parent link="ball"/>
    <child link="panda_link10"/>
    <axis xyz="0 0 1"/>
    <dynamics damping="1"/>
  </joint>
  <!-- end of ball joint -->
  <link name="panda_link_box">
    <inertial>
      <origin rpy="0 0 0" xyz="0 0 0.075"/>
      <mass value="2"/>
      <inertia ixx="0.007225" ixy="0.0" ixz="0.0" iyy="0.00578125" iyz="0.0" izz="0.00175625"/>
    </inertial>
    <visual>
      <geometry>
        <box size="0.025 0.08 0.15"/>
      </geometry>
      <origin rpy="0 0 0" xyz="0 0 0.075"/>
    </visual>
    <collision>
      <geometry>
        <box size="0.025 0.08 0.15"/>
      </geometry>
      <origin rpy="0 0 0" xyz="0 0 0.075"/>
    </collision>
  </link>
  <joint name="panda_box" type="fixed">
    <origin rpy="0 -1.5707963267948966 0" xyz="0.075 0 0.0375"/>
    <parent link="panda_link10"/>
    <child link="panda_link_box"/>
    <axis xyz="0 0 0"/>
  </joint>
  <link name="panda_link_handle">
    <inertial>
      <origin rpy="0 0 0" xyz="0 0 0.025"/>
      <mass value="0.1"/>
      <inertia ixx="3.64583e-03" ixy="0.0" ixz="0.0" iyy="3.64583e-03" iyz="0.0" izz="3.125e-03"/>
    </inertial>
    <visual>
      <geometry>
        <cylinder length="0.05" radius="0.01"/>
      </geometry>
      <origin rpy="0 0 0" xyz="0 0 0.025"/>
    </visual>
    <collision>
      <geometry>
        <cylinder length="0.05" radius="0.01"/>
      </geometry>
      <origin rpy="0 0 0" xyz="0 0 0.025"/>
    </collision>
  </link>
  <joint name="panda_handle" type="fixed">
    <origin rpy="0 1.5707963267948966 0" xyz="0.0125 0 0.075"/>
    <parent link="panda_link_box"/>
    <child link="panda_link_handle"/>
    <axis xyz="0 0 0"/>
  </joint>
  <!--
    <link name="ft_link">
      <inertial>
        <origin xyz="0 0 0" rpy="0 0 0"/>
        <mass value="0.1"/>
        <inertia ixx="0.007225" ixy="0.0" ixz="0.0" iyy="0.00578125" iyz="0.0" izz="0.00175625"/>
      </inertial>

      <visual>
        <geometry>
          <box size="0.001 0.001 0.001"/>
        </geometry>
        <origin xyz="0 0 0" rpy="${rpy}"/>
      </visual>
      
       <collision>
        <geometry>
          <box size="0.001 0.001 0.001"/>
        </geometry>
        <origin xyz="0 0 0" rpy="${rpy}"/>    
      </collision>
      
    </link>
    
    <joint name="handle_to_ft" type="revolute">
      <origin rpy="0 ${pi} 0" xyz="0 0 0.025"/>
      <parent link="${arm_id}_link_handle"/>
      <child link="ft_link"/>
      <limit effort="12" lower="0" upper="0" velocity="2.6100"/>
      <axis xyz="0 0 1" />
    </joint>

    <link name="arm_link_2">
      <inertial>
        <origin xyz="0 0 0.1" rpy="0 0 0"/>
        <mass value="0.1"/>
        <inertia ixx="3.64583e-03" ixy="0.0" ixz="0.0" iyy="3.64583e-03" iyz="0.0" izz="3.125e-03"/>
      </inertial>

      <visual>
        <geometry>
          <cylinder length="0.2" radius="0.01"/>
        </geometry>
        <origin xyz="0 0 0.1" rpy="0 0 0"/>
      </visual>
      
      <collision>
        <geometry>
          <cylinder length="0.01" radius="0.01"/>
        </geometry>
        <origin xyz="0 0 0.1" rpy="0 0 0"/>   
      </collision>
      
    </link>
    
    <link name="arm_link_1">
      <inertial>
        <origin xyz="0 0 0.1" rpy="0 0 0"/>
        <mass value="0.1"/>
        <inertia ixx="3.64583e-03" ixy="0.0" ixz="0.0" iyy="3.64583e-03" iyz="0.0" izz="3.125e-03"/>
      </inertial>

      <visual>
        <geometry>
          <cylinder length="0.2" radius="0.01"/>
        </geometry>
        <origin xyz="0 0 0.1" rpy="0 0 0"/>
      </visual>
      
      <collision>
        <geometry>
          <cylinder length="0.01" radius="0.01"/>
        </geometry>
        <origin xyz="0 0 0.1" rpy="0 0 0"/>   
      </collision>
    </link>
    
    <joint name="ft_to_arm2" type="revolute">
      <origin rpy="0 ${pi/2} ${-pi/4}" xyz="0 0 0"/>
      <parent link="ft_link"/>
      <child link="arm_link_2"/>
      <limit effort="12" lower="${-pi}" upper="${pi}" velocity="2.6100"/>
      <axis xyz="1 0 0" />
    </joint>

    <joint name="arm2_to_arm1" type="revolute">
      <origin rpy="${-pi/2} 0 0" xyz="0 0 0.2"/>
      <parent link="arm_link_2"/>
      <child link="arm_link_1"/>
      <limit effort="12" lower="${-pi}" upper="${pi}" velocity="2.6100"/>
      <axis xyz="1 0 0" />
    </joint>

    <link name="arm_base">
      <inertial>
        <origin xyz="0 0 0" rpy="0 0 0"/>
        <mass value="0.1"/>
        <inertia ixx="0.007225" ixy="0.0" ixz="0.0" iyy="0.00578125" iyz="0.0" izz="0.00175625"/>
      </inertial>

      <visual>
        <geometry>
          <box size="0.001 0.001 0.001"/>
        </geometry>
        <origin xyz="0 0 0" rpy="${rpy}"/>
      </visual>
      
       <collision>
        <geometry>
          <box size="0.001 0.001 0.001"/>
        </geometry>
        <origin xyz="0 0 0" rpy="${rpy}"/>    
      </collision>
      
    </link>

    <joint name="arm1_to_base" type="revolute">
      <origin rpy="${pi/2} ${-pi/4} ${-pi/2}" xyz="0 0 0.2"/>
      <parent link="arm_link_1"/>
      <child link="arm_base"/>
      <limit effort="12" lower="${-pi}" upper="${pi}" velocity="2.6100"/>
      <axis xyz="0 0 1" />
    </joint>

    <gazebo>
      <joint name="base_to_world" type="fixed">
        <child>world</child>
        <parent>arm_base</parent>
      </joint>
    </gazebo>
    
-->
  <!--Ensures collision of added handle-->
  <!--
    <gazebo reference="${arm_id}_link10">
      <selfCollide>true</selfCollide>
    </gazebo>
    -->
  <!--Force torque sensor plugin -->
  <!--
    <gazebo reference="handle_to_ft">
      <provideFeedback>true</provideFeedback>
    </gazebo>

    <gazebo>
        <plugin name="ft_sensor" filename="libgazebo_ros_ft_sensor.so">
            <updateRate>97.0</updateRate>
            <topicName>ft_sensor_topic</topicName>
            <jointName>handle_to_ft</jointName>
        </plugin>
    </gazebo>
-->
  <!-- link 0 -->
  <gazebo reference="panda_link0">
    <material>Gazebo/Grey</material>
    <mu1>0.2</mu1>
    <mu2>0.2</mu2>
  </gazebo>
  <!-- link/joint 1 -->
  <gazebo reference="panda_link1">
    <material>Gazebo/White</material>
    <mu1>0.2</mu1>
    <mu2>0.2</mu2>
  </gazebo>
  <gazebo reference="panda_joint1">
    <implicitSpringDamper>1</implicitSpringDamper>
    <provideFeedback>true</provideFeedback>
  </gazebo>
  <!-- link/joint 2 -->
  <gazebo reference="panda_link2">
    <material>Gazebo/White</material>
    <mu1>0.2</mu1>
    <mu2>0.2</mu2>
  </gazebo>
  <gazebo reference="panda_joint2">
    <implicitSpringDamper>1</implicitSpringDamper>
    <provideFeedback>true</provideFeedback>
  </gazebo>
  <!-- link/joint 3 -->
  <gazebo reference="panda_link3">
    <material>Gazebo/White</material>
    <mu1>0.2</mu1>
    <mu2>0.2</mu2>
  </gazebo>
  <gazebo reference="panda_joint3">
    <implicitSpringDamper>1</implicitSpringDamper>
    <provideFeedback>true</provideFeedback>
  </gazebo>
  <!-- link/joint 4 -->
  <gazebo reference="panda_link4">
    <material>Gazebo/White</material>
    <mu1>0.2</mu1>
    <mu2>0.2</mu2>
  </gazebo>
  <gazebo reference="panda_joint4">
    <implicitSpringDamper>1</implicitSpringDamper>
    <provideFeedback>true</provideFeedback>
  </gazebo>
  <!-- link/joint 5 -->
  <gazebo reference="panda_link5">
    <material>Gazebo/White</material>
    <mu1>0.2</mu1>
    <mu2>0.2</mu2>
  </gazebo>
  <gazebo reference="panda_joint5">
    <implicitSpringDamper>1</implicitSpringDamper>
    <provideFeedback>true</provideFeedback>
  </gazebo>
  <!-- link/joint 6 -->
  <gazebo reference="panda_link6">
    <material>Gazebo/White</material>
    <mu1>0.2</mu1>
    <mu2>0.2</mu2>
  </gazebo>
  <gazebo reference="panda_joint6">
    <implicitSpringDamper>1</implicitSpringDamper>
    <provideFeedback>true</provideFeedback>
  </gazebo>
  <!-- link/joint 7 -->
  <gazebo reference="panda_link7">
    <material>Gazebo/Grey</material>
    <mu1>0.2</mu1>
    <mu2>0.2</mu2>
  </gazebo>
  <gazebo reference="panda_joint7">
    <implicitSpringDamper>1</implicitSpringDamper>
    <provideFeedback>true</provideFeedback>
  </gazebo>
  <!-- link/joint 8 -->
  <gazebo reference="panda_link8">
    <material>Gazebo/Grey</material>
    <mu1>0.2</mu1>
    <mu2>0.2</mu2>
  </gazebo>
  <!-- link/joint hand -->
  <gazebo reference="panda_hand">
    <material>Gazebo/Grey</material>
    <mu1>0.2</mu1>
    <mu2>0.2</mu2>
  </gazebo>
  <!-- Load Gazebo lib with desired parameters -->
  <gazebo>
    <plugin filename="libgazebo_ros_control.so" name="gazebo_ros_control">
        </plugin>
  </gazebo>
  <!-- transmission joint 1 -->
  <transmission name="panda_tran_1">
    <type>transmission_interface/SimpleTransmission</type>
    <joint name="panda_joint1">
      <hardwareInterface>hardware_interface/EffortJointInterface</hardwareInterface>
    </joint>
    <actuator name="panda_motor_1">
      <hardwareInterface>hardware_interface/EffortJointInterface</hardwareInterface>
      <mechanicalReduction>1</mechanicalReduction>
    </actuator>
  </transmission>
  <!-- transmission joint 2 -->
  <transmission name="panda_tran_2">
    <type>transmission_interface/SimpleTransmission</type>
    <joint name="panda_joint2">
      <hardwareInterface>hardware_interface/EffortJointInterface</hardwareInterface>
    </joint>
    <actuator name="panda_motor_2">
      <hardwareInterface>hardware_interface/EffortJointInterface</hardwareInterface>
      <mechanicalReduction>1</mechanicalReduction>
    </actuator>
  </transmission>
  <!-- transmission joint 3 -->
  <transmission name="panda_tran_3">
    <type>transmission_interface/SimpleTransmission</type>
    <joint name="panda_joint3">
      <hardwareInterface>hardware_interface/EffortJointInterface</hardwareInterface>
    </joint>
    <actuator name="panda_motor_3">
      <hardwareInterface>hardware_interface/EffortJointInterface</hardwareInterface>
      <mechanicalReduction>1</mechanicalReduction>
    </actuator>
  </transmission>
  <!-- transmission joint 4 -->
  <transmission name="panda_tran_4">
    <type>transmission_interface/SimpleTransmission</type>
    <joint name="panda_joint4">
      <hardwareInterface>hardware_interface/EffortJointInterface</hardwareInterface>
    </joint>
    <actuator name="panda_motor_4">
      <hardwareInterface>hardware_interface/EffortJointInterface</hardwareInterface>
      <mechanicalReduction>1</mechanicalReduction>
    </actuator>
  </transmission>
  <!-- transmission joint 5 -->
  <transmission name="panda_tran_5">
    <type>transmission_interface/SimpleTransmission</type>
    <joint name="panda_joint5">
      <hardwareInterface>hardware_interface/EffortJointInterface</hardwareInterface>
    </joint>
    <actuator name="panda_motor_5">
      <hardwareInterface>hardware_interface/EffortJointInterface</hardwareInterface>
      <mechanicalReduction>1</mechanicalReduction>
    </actuator>
  </transmission>
  <!-- transmission joint 6 -->
  <transmission name="panda_tran_6">
    <type>transmission_interface/SimpleTransmission</type>
    <joint name="panda_joint6">
      <hardwareInterface>hardware_interface/EffortJointInterface</hardwareInterface>
    </joint>
    <actuator name="panda_motor_6">
      <hardwareInterface>hardware_interface/EffortJointInterface</hardwareInterface>
      <mechanicalReduction>1</mechanicalReduction>
    </actuator>
  </transmission>
  <!-- transmission joint 7 -->
  <transmission name="panda_tran_7">
    <type>transmission_interface/SimpleTransmission</type>
    <joint name="panda_joint7">
      <hardwareInterface>hardware_interface/EffortJointInterface</hardwareInterface>
    </joint>
    <actuator name="panda_motor_7">
      <hardwareInterface>hardware_interface/EffortJointInterface</hardwareInterface>
      <mechanicalReduction>1</mechanicalReduction>
    </actuator>
  </transmission>
  <transmission name="panda_tran_x">
    <type>transmission_interface/SimpleTransmission</type>
    <joint name="panda_joint_ball_x">
      <hardwareInterface>hardware_interface/EffortJointInterface</hardwareInterface>
    </joint>
    <actuator name="panda_motor_x">
      <hardwareInterface>hardware_interface/EffortJointInterface</hardwareInterface>
      <mechanicalReduction>1</mechanicalReduction>
    </actuator>
  </transmission>
  <transmission name="panda_tran_y">
    <type>transmission_interface/SimpleTransmission</type>
    <joint name="panda_joint_ball_y">
      <hardwareInterface>hardware_interface/EffortJointInterface</hardwareInterface>
    </joint>
    <actuator name="panda_motor_y">
      <hardwareInterface>hardware_interface/EffortJointInterface</hardwareInterface>
      <mechanicalReduction>1</mechanicalReduction>
    </actuator>
  </transmission>
  <transmission name="panda_tran_z">
    <type>transmission_interface/SimpleTransmission</type>
    <joint name="panda_joint_ball_z">
      <hardwareInterface>hardware_interface/EffortJointInterface</hardwareInterface>
    </joint>
    <actuator name="panda_motor_z">
      <hardwareInterface>hardware_interface/EffortJointInterface</hardwareInterface>
      <mechanicalReduction>1</mechanicalReduction>
    </actuator>
  </transmission>
  <!--
      <transmission name="arm2_to_arm1_tran">

        <type>transmission_interface/SimpleTransmission</type>

        <joint name="arm2_to_arm1">
            <hardwareInterface>hardware_interface/EffortJointInterface</hardwareInterface>
        </joint>

        <actuator name="arm2_to_arm1_motor">
          <hardwareInterface>hardware_interface/EffortJointInterface</hardwareInterface>
          <mechanicalReduction>1</mechanicalReduction>
        </actuator>
      </transmission>

      <transmission name="arm1_to_base_tran">

        <type>transmission_interface/SimpleTransmission</type>

        <joint name="arm1_to_base">
            <hardwareInterface>hardware_interface/EffortJointInterface</hardwareInterface>
        </joint>

        <actuator name="arm1_to_base_motor">
          <hardwareInterface>hardware_interface/EffortJointInterface</hardwareInterface>
          <mechanicalReduction>1</mechanicalReduction>
        </actuator>
      </transmission>

  -->
</robot>

